<?xml version="1.0"?>
<robot name="mecanum_robot">
  
  <!-- 
    Robot Specifications from ESP32 Firmware:
    - Wheelbase Width: 468.5mm (0.4685m) center-to-center L/R
    - Wheelbase Length: 420mm (0.420m) center-to-center F/B  
    - Wheel Radius: 76.2mm (0.0762m) - 152mm diameter
    - Chassis: 460mm x 360mm aluminum extrusion
  -->
  
  <!-- Base Link - Main body of the robot -->
  <link name="base_link">
    <visual>
      <geometry>
        <box size="0.46 0.36 0.1"/>  <!-- 460mm x 360mm x 100mm -->
      </geometry>
      <origin xyz="0 0 0.05" rpy="0 0 0"/>
      <material name="blue">
        <color rgba="0.2 0.4 0.8 1.0"/>
      </material>
    </visual>
    <collision>
      <geometry>
        <box size="0.46 0.36 0.1"/>
      </geometry>
      <origin xyz="0 0 0.05" rpy="0 0 0"/>
    </collision>
    <inertial>
      <mass value="15.0"/>  <!-- Approximate robot mass -->
      <origin xyz="0 0 0.05" rpy="0 0 0"/>
      <inertia ixx="0.5" ixy="0.0" ixz="0.0" iyy="0.5" iyz="0.0" izz="0.8"/>
    </inertial>
  </link>

  <!-- Front Left Wheel -->
  <link name="front_left_wheel">
    <visual>
      <geometry>
        <cylinder radius="0.0762" length="0.0555"/>  <!-- 76.2mm radius, 55.5mm width -->
      </geometry>
      <origin xyz="0 0 0" rpy="1.5708 0 0"/>
      <material name="black">
        <color rgba="0.1 0.1 0.1 1.0"/>
      </material>
    </visual>
    <collision>
      <geometry>
        <cylinder radius="0.0762" length="0.0555"/>
      </geometry>
      <origin xyz="0 0 0" rpy="1.5708 0 0"/>
    </collision>
    <inertial>
      <mass value="1.0"/>
      <inertia ixx="0.01" ixy="0.0" ixz="0.0" iyy="0.01" iyz="0.0" izz="0.01"/>
    </inertial>
  </link>

  <joint name="front_left_wheel_joint" type="continuous">
    <parent link="base_link"/>
    <child link="front_left_wheel"/>
    <origin xyz="0.21 0.23425 0" rpy="0 0 0"/>  <!-- F/B: 420mm/2=210mm, L/R: 468.5mm/2=234.25mm -->
    <axis xyz="0 1 0"/>
  </joint>

  <!-- Front Right Wheel -->
  <link name="front_right_wheel">
    <visual>
      <geometry>
        <cylinder radius="0.0762" length="0.0555"/>
      </geometry>
      <origin xyz="0 0 0" rpy="1.5708 0 0"/>
      <material name="black">
        <color rgba="0.1 0.1 0.1 1.0"/>
      </material>
    </visual>
    <collision>
      <geometry>
        <cylinder radius="0.0762" length="0.0555"/>
      </geometry>
      <origin xyz="0 0 0" rpy="1.5708 0 0"/>
    </collision>
    <inertial>
      <mass value="1.0"/>
      <inertia ixx="0.01" ixy="0.0" ixz="0.0" iyy="0.01" iyz="0.0" izz="0.01"/>
    </inertial>
  </link>

  <joint name="front_right_wheel_joint" type="continuous">
    <parent link="base_link"/>
    <child link="front_right_wheel"/>
    <origin xyz="0.21 -0.23425 0" rpy="0 0 0"/>
    <axis xyz="0 1 0"/>
  </joint>

  <!-- Rear Left Wheel -->
  <link name="rear_left_wheel">
    <visual>
      <geometry>
        <cylinder radius="0.0762" length="0.0555"/>
      </geometry>
      <origin xyz="0 0 0" rpy="1.5708 0 0"/>
      <material name="black">
        <color rgba="0.1 0.1 0.1 1.0"/>
      </material>
    </visual>
    <collision>
      <geometry>
        <cylinder radius="0.0762" length="0.0555"/>
      </geometry>
      <origin xyz="0 0 0" rpy="1.5708 0 0"/>
    </collision>
    <inertial>
      <mass value="1.0"/>
      <inertia ixx="0.01" ixy="0.0" ixz="0.0" iyy="0.01" iyz="0.0" izz="0.01"/>
    </inertial>
  </link>

  <joint name="rear_left_wheel_joint" type="continuous">
    <parent link="base_link"/>
    <child link="rear_left_wheel"/>
    <origin xyz="-0.21 0.23425 0" rpy="0 0 0"/>
    <axis xyz="0 1 0"/>
  </joint>

  <!-- Rear Right Wheel -->
  <link name="rear_right_wheel">
    <visual>
      <geometry>
        <cylinder radius="0.0762" length="0.0555"/>
      </geometry>
      <origin xyz="0 0 0" rpy="1.5708 0 0"/>
      <material name="black">
        <color rgba="0.1 0.1 0.1 1.0"/>
      </material>
    </visual>
    <collision>
      <geometry>
        <cylinder radius="0.0762" length="0.0555"/>
      </geometry>
      <origin xyz="0 0 0" rpy="1.5708 0 0"/>
    </collision>
    <inertial>
      <mass value="1.0"/>
      <inertia ixx="0.01" ixy="0.0" ixz="0.0" iyy="0.01" iyz="0.0" izz="0.01"/>
    </inertial>
  </link>

  <joint name="rear_right_wheel_joint" type="continuous">
    <parent link="base_link"/>
    <child link="rear_right_wheel"/>
    <origin xyz="-0.21 -0.23425 0" rpy="0 0 0"/>
    <axis xyz="0 1 0"/>
  </joint>

  <!-- Optional: Add a direction indicator (arrow on top) -->
  <link name="direction_indicator">
    <visual>
      <geometry>
        <box size="0.15 0.03 0.01"/>  <!-- Larger arrow for better visibility -->
      </geometry>
      <origin xyz="0.075 0 0" rpy="0 0 0"/>
      <material name="red">
        <color rgba="1.0 0.2 0.2 1.0"/>
      </material>
    </visual>
  </link>

  <joint name="direction_indicator_joint" type="fixed">
    <parent link="base_link"/>
    <child link="direction_indicator"/>
    <origin xyz="0.15 0 0.11" rpy="0 0 0"/>
  </joint>

  <!-- ============================================================ -->
  <!-- Nav2 Sensor Frames - STANDARD APPROACH                       -->
  <!-- TF Tree: odom → base_link → camera_link, laser_frame, etc   -->
  <!-- ============================================================ -->

  <!-- Base Footprint for Nav2 -->
  <link name="base_footprint"/>
  <joint name="base_footprint_joint" type="fixed">
    <parent link="base_footprint"/>
    <child link="base_link"/>
    <origin xyz="0 0 0.0762" rpy="0 0 0"/>  <!-- base_link is wheel radius above ground -->
  </joint>

  <!-- ZED2 Camera Link - CHILD of base_link (STANDARD!) -->
  <link name="camera_link">
    <visual>
      <geometry>
        <box size="0.175 0.030 0.033"/>
      </geometry>
      <material name="dark_gray">
        <color rgba="0.3 0.3 0.3 1.0"/>
      </material>
    </visual>
  </link>
  
  <joint name="camera_joint" type="fixed">
    <parent link="base_link"/>
    <child link="camera_link"/>
    <origin xyz="0.23 0 0.1" rpy="0 0 0"/>  <!-- Front, centered, on top -->
  </joint>

  <!-- Laser Frame for depth_to_laserscan -->
  <link name="laser_frame"/>
  <joint name="laser_joint" type="fixed">
    <parent link="base_link"/>
    <child link="laser_frame"/>
    <origin xyz="0.23 0 0.05" rpy="0 0 0"/>  <!-- Same x as camera, lower z -->
  </joint>

  <!-- IMU Frame -->
  <link name="imu_link"/>
  <joint name="imu_joint" type="fixed">
    <parent link="camera_link"/>
    <child link="imu_link"/>
    <origin xyz="0 0 0" rpy="0 0 0"/>  <!-- Inside camera -->
  </joint>

</robot>
